{
  "url": "https://api.github.com/repos/quarkusio/quarkus/issues/26821",
  "repository_url": "https://api.github.com/repos/quarkusio/quarkus",
  "labels_url": "https://api.github.com/repos/quarkusio/quarkus/issues/26821/labels{/name}",
  "comments_url": "https://api.github.com/repos/quarkusio/quarkus/issues/26821/comments",
  "events_url": "https://api.github.com/repos/quarkusio/quarkus/issues/26821/events",
  "html_url": "https://github.com/quarkusio/quarkus/issues/26821",
  "id": 1309867646,
  "node_id": "I_kwDOCFbutM5OEv5-",
  "number": 26821,
  "title": "Fault Tolerance - Retry not working with Vertx's WebClient",
  "labels": [
    {
      "id": 985346620,
      "node_id": "MDU6TGFiZWw5ODUzNDY2MjA=",
      "url": "https://api.github.com/repos/quarkusio/quarkus/labels/kind/bug",
      "name": "kind/bug",
      "color": "d73a4a",
      "default": false,
      "description": "Something isn't working"
    },
    {
      "id": 1283619446,
      "node_id": "MDU6TGFiZWwxMjgzNjE5NDQ2",
      "url": "https://api.github.com/repos/quarkusio/quarkus/labels/area/smallrye",
      "name": "area/smallrye",
      "color": "0366d6",
      "default": false,
      "description": ""
    },
    {
      "id": 2236032526,
      "node_id": "MDU6TGFiZWwyMjM2MDMyNTI2",
      "url": "https://api.github.com/repos/quarkusio/quarkus/labels/area/fault-tolerance",
      "name": "area/fault-tolerance",
      "color": "0366d6",
      "default": false,
      "description": ""
    }
  ],
  "state": "closed",
  "locked": false,
  "milestone": null,
  "comments": 4,
  "created_at": "2022-07-19T18:01:47Z",
  "updated_at": "2022-07-20T21:48:29Z",
  "closed_at": "2022-07-20T07:29:17Z",
  "active_lock_reason": null,
  "body": "### Describe the bug\r\n\r\nI need to request info from an external service; said service is not that reliable, so it could fail under several circumstances. While implementing a Retry strategy, i found that it does not always work.\r\n\r\n\r\n### Expected behavior\r\n\r\nI expect APIClientVerticle.sendRequest to be called 5 times in a row when making a request to http://localhost:8081/retrySkipped\r\n\r\n### Actual behavior\r\n\r\nThe exception is thrown right away; it does not seems to be catched by the retry mechanism:\r\n\r\n            try {\r\n                CompletionStages.propagateCompletion((CompletionStage)this.delegate.apply(ctx), result);\r\n            } catch (Exception var4) {\r\n                result.completeExceptionally(var4); // the debugger does not stop here for {host}/retrySkipped\r\n            }\r\n\r\n\r\n\r\n### How to Reproduce?\r\n\r\nReproducer: https://gitlab.com/gus.gramajo/quarkus-ft-retry-reproducer\r\n\r\nSteps to repro:\r\n\r\n1 - ./mvnw quarkus: dev\r\n2 - Make a request to http://localhost:8081/retryWorks\r\n3 - Make a request to http://localhost:8081/retrySkipped\r\n\r\n### Quarkus version or git rev\r\n\r\n2.9.1.Final, 2.10.2.Final\r\n",
  "reactions": {
    "url": "https://api.github.com/repos/quarkusio/quarkus/issues/26821/reactions",
    "total_count": 0,
    "+1": 0,
    "-1": 0,
    "laugh": 0,
    "hooray": 0,
    "confused": 0,
    "heart": 0,
    "rocket": 0,
    "eyes": 0
  },
  "timeline_url": "https://api.github.com/repos/quarkusio/quarkus/issues/26821/timeline",
  "performed_via_github_app": null,
  "state_reason": "not_planned"
}
