{
  "url": "https://api.github.com/repos/quarkusio/quarkus/issues/33572",
  "repository_url": "https://api.github.com/repos/quarkusio/quarkus",
  "labels_url": "https://api.github.com/repos/quarkusio/quarkus/issues/33572/labels{/name}",
  "comments_url": "https://api.github.com/repos/quarkusio/quarkus/issues/33572/comments",
  "events_url": "https://api.github.com/repos/quarkusio/quarkus/issues/33572/events",
  "html_url": "https://github.com/quarkusio/quarkus/issues/33572",
  "id": 1723333322,
  "node_id": "I_kwDOCFbutM5mt_rK",
  "number": 33572,
  "title": "Can't catch exception from method annotated with @WithTransaction and @WithSessionOnDemand",
  "labels": [
    {
      "id": 985346620,
      "node_id": "MDU6TGFiZWw5ODUzNDY2MjA=",
      "url": "https://api.github.com/repos/quarkusio/quarkus/labels/kind/bug",
      "name": "kind/bug",
      "color": "d73a4a",
      "default": false,
      "description": "Something isn't working"
    },
    {
      "id": 2122256208,
      "node_id": "MDU6TGFiZWwyMTIyMjU2MjA4",
      "url": "https://api.github.com/repos/quarkusio/quarkus/labels/area/hibernate-reactive",
      "name": "area/hibernate-reactive",
      "color": "0366d6",
      "default": false,
      "description": ""
    }
  ],
  "state": "open",
  "locked": false,
  "milestone": null,
  "comments": 2,
  "created_at": "2023-05-24T07:13:58Z",
  "updated_at": "2023-05-29T14:31:32Z",
  "closed_at": null,
  "active_lock_reason": null,
  "body": "### Describe the bug\n\nMy business method is annotate with `@WithTransaction` and `@WithSessionOnDemand`:\r\n\r\n```\r\n@WithTransaction\r\n@WithSessionOnDemand\r\npublic Uni<MyTestModel> action(MyTestModel form) {\r\n    throw new RuntimeException(\"Test exception\");\r\n}\r\n```\r\n\r\nIn the REST service method the business method is wrapped in a `try-catch` block because I want to show the possible exception to the use through by my own user interface.\r\n\r\n```\r\n@POST\r\n@Consumes(MediaType.APPLICATION_FORM_URLENCODED)\r\n@Produces(MediaType.TEXT_HTML)\r\npublic TemplateInstance action(@BeanParam MyTestModel form) {\r\n     try {\r\n          var model = service.action(form)\r\n               .memoize()\r\n               .indefinitely();\r\n          return MyTestPage.Templates.test()\r\n                 .data(\"model\", model);\r\n    } catch (RuntimeException ex) {\r\n         form.setMessage(ex.getMessage());\r\n         return MyTestPage.Templates.test()\r\n               .data(\"model\", form);\r\n   }\r\n}\r\n```\r\n\n\n### Expected behavior\n\nI want to view the exception in through by my own user interface.\n\n### Actual behavior\n\nQuarkus seems to ignore the `try-catch` block and emits the exception by itself.\n\n### How to Reproduce?\n\nReproducer: [quarkustest.zip](https://github.com/quarkusio/quarkus/files/11551485/quarkustest.zip)\r\n\r\nThe demo includes a `docker-compose.yaml` to run a PostgresSQL container.\r\n\n\n### Output of `uname -a` or `ver`\n\nMAC OSX 13.3.1 x86_64\n\n### Output of `java -version`\n\n17.0.6\n\n### GraalVM version (if different from Java)\n\n_No response_\n\n### Quarkus version or git rev\n\n3.0.3\n\n### Build tool (ie. output of `mvnw --version` or `gradlew --version`)\n\nmaven 3.8.8\n\n### Additional information\n\nIf I apply only the `WithTransaction` annotation to my business method, nothing change.  \r\nIf I apply only the `WithSessionOnDemabd` annotation to my business method, nothing change.  \r\nIf don't apply any annotation to my business method, I can see the exception through by my own user interface.",
  "reactions": {
    "url": "https://api.github.com/repos/quarkusio/quarkus/issues/33572/reactions",
    "total_count": 0,
    "+1": 0,
    "-1": 0,
    "laugh": 0,
    "hooray": 0,
    "confused": 0,
    "heart": 0,
    "rocket": 0,
    "eyes": 0
  },
  "timeline_url": "https://api.github.com/repos/quarkusio/quarkus/issues/33572/timeline",
  "performed_via_github_app": null,
  "state_reason": null
}
