{
  "url": "https://api.github.com/repos/quarkusio/quarkus/issues/39393",
  "repository_url": "https://api.github.com/repos/quarkusio/quarkus",
  "labels_url": "https://api.github.com/repos/quarkusio/quarkus/issues/39393/labels{/name}",
  "comments_url": "https://api.github.com/repos/quarkusio/quarkus/issues/39393/comments",
  "events_url": "https://api.github.com/repos/quarkusio/quarkus/issues/39393/events",
  "html_url": "https://github.com/quarkusio/quarkus/issues/39393",
  "id": 2183614522,
  "node_id": "I_kwDOCFbutM6CJ1A6",
  "number": 39393,
  "title": "Exception on amqp connection at the end of each test when application terminates",
  "labels": [
    {
      "id": 985346620,
      "node_id": "MDU6TGFiZWw5ODUzNDY2MjA=",
      "url": "https://api.github.com/repos/quarkusio/quarkus/labels/kind/bug",
      "name": "kind/bug",
      "color": "d73a4a",
      "default": false,
      "description": "Something isn't working"
    },
    {
      "id": 1341157944,
      "node_id": "MDU6TGFiZWwxMzQxMTU3OTQ0",
      "url": "https://api.github.com/repos/quarkusio/quarkus/labels/triage/upstream",
      "name": "triage/upstream",
      "color": "7db4d8",
      "default": false,
      "description": "Used for issues which are caused by issues in upstream projects/dependency"
    },
    {
      "id": 1416364896,
      "node_id": "MDU6TGFiZWwxNDE2MzY0ODk2",
      "url": "https://api.github.com/repos/quarkusio/quarkus/labels/area/reactive-messaging",
      "name": "area/reactive-messaging",
      "color": "0366d6",
      "default": false,
      "description": ""
    }
  ],
  "state": "closed",
  "locked": false,
  "milestone": null,
  "comments": 6,
  "created_at": "2024-03-13T10:15:59Z",
  "updated_at": "2024-03-14T07:09:50Z",
  "closed_at": "2024-03-14T07:09:50Z",
  "active_lock_reason": null,
  "body": "### Describe the bug\r\n\r\nWhen running my tests I am observing the following exception all the time: \r\n```\r\nMutiny had to drop the following exception [Error Occurred After Shutdown]\r\nio.vertx.core.impl.NoStackTraceThrowable: Connection disconnected\r\n```\r\n\r\nThis started when I introduced smallrye reactive messaging to communicate with an AMQP broker. \r\nIt seems whenever the application terminates during tests the amqp connection is interrupted and that exception is thrown. \r\nAlso setting `quarkus.shutdown.timeout` doesn't help.  The amqp connection should be gracefulfy terminated\r\n\r\n### Expected behavior\r\n\r\nNo exception after each test run\r\nThe amqp connection should be gracefufly terminated\r\n\r\n### Actual behavior\r\n\r\nNot impacting the test but throwing that exception in the output after each test. \r\n\r\n### How to Reproduce?\r\n\r\nI set up this small app for you to quickly reproduce. You just need to run the [GreetingResourceTest.java](https://github.com/mnguetsa/quarkus-reproducer/blob/amqp/src/test/java/org/acme/GreetingResourceTest.java) and you can see the exception already.\r\nCheckout the **amqp** branch here: https://github.com/mnguetsa/quarkus-reproducer/tree/amqp\r\n\r\n### Output of `uname -a` or `ver`\r\n\r\n_No response_\r\n\r\n### Output of `java -version`\r\n\r\n21\r\n\r\n### Quarkus version or git rev\r\n\r\n3.8.1\r\n\r\n### Build tool (ie. output of `mvnw --version` or `gradlew --version`)\r\n\r\ngradle 8.5\r\n\r\n### Additional information\r\n\r\n_No response_",
  "reactions": {
    "url": "https://api.github.com/repos/quarkusio/quarkus/issues/39393/reactions",
    "total_count": 0,
    "+1": 0,
    "-1": 0,
    "laugh": 0,
    "hooray": 0,
    "confused": 0,
    "heart": 0,
    "rocket": 0,
    "eyes": 0
  },
  "timeline_url": "https://api.github.com/repos/quarkusio/quarkus/issues/39393/timeline",
  "performed_via_github_app": null,
  "state_reason": "completed"
}
